Workbook

Sheet Summary
A1: CORPORATE CREDIT MEMO — CVS Health Corporation (NYSE: CVS)
A2: Prepared by: Archit Chawla | Date: October 20, 2026 | Independent research project — not investment advice and not a credit rating.
A4: RECOMMENDATION: APPROVE — maintain investment-grade senior unsecured exposure (conditions in memo)
A5: Shadow rating: BBB, stable outlook (agency ratings for reference: Moody's Baa3 stable / S&P BBB / Fitch BBB negative)
A7: Headline ratios (live-linked to Ratios sheet)
B8: FY2023 | C8: FY2024 | D8: FY2025 | E8: LTM Jun-26
A9: Total debt ($M) | B9: =Ratios!D12 | C9: =Ratios!E12 | D9: =Ratios!F12 | E9: =Ratios!G12
A10: Adjusted EBITDA ($M) | B10: =Ratios!D10 | C10: =Ratios!E10 | D10: =Ratios!F10 | E10: =Ratios!G10
A11: Gross leverage (adj.) | B11: =Ratios!D15 | C11: =Ratios!E15 | D11: =Ratios!F15 | E11: =Ratios!G15
A12: Net leverage (adj.) | B12: =Ratios!D17 | C12: =Ratios!E17 | D12: =Ratios!F17 | E12: =Ratios!G17
A13: Interest coverage (adj.) | B13: =Ratios!D18 | C13: =Ratios!E18 | D13: =Ratios!F18 | E13: =Ratios!G18
A14: FFO / Debt | B14: =Ratios!D21 | C14: =Ratios!E21 | D14: =Ratios!F21 | E14: =Ratios!G21
A15: FCF after dividends ($M) | B15: =Ratios!D22 | C15: =Ratios!E22 | D15: =Ratios!F22 | E15: =Ratios!G22
A16: Lease-adjusted leverage | B16: =Ratios!D25 | C16: =Ratios!E25 | D16: =Ratios!F25 | E16: =Ratios!G25
A18: Key facts (Jun 30, 2026 unless noted)
A19: Total debt | B19: =Ratios!G12 | C19: down from $66,270M at Dec 31, 2024 (peak)
A20: Cash | B20: =Ratios!G13 | C20: ~$2,700M held at parent / non-restricted subsidiaries
A21: Undrawn revolvers | B21: =Inputs!B51 | C21: 3 x $2,500M back-up facilities, expire May 2029/30/31
A22: 2027 debt maturities (principal) | B22: =Inputs!B41 | C22: per Dec 31, 2025 maturity ladder
A23: LTM revenues | B23: =Ratios!G5
A24: LTM FFO / Debt | B24: =Ratios!G21
A26: Verification
A27: Model recalculated in LibreOffice headless after build; every Ratios value checked against an independent Python computation from data/inputs.json (see memo, Methodology & Verification). Inputs tie to EDGAR company facts for CIK 0000064803 pulled 2026-10-20.

Sheet Inputs
A1: CVS Health Corporation (NYSE: CVS) — Credit Model Inputs
A2: All figures $ millions (shares in millions). Source: SEC EDGAR company facts, CIK 0000064803, pulled 2026-10-20 (see pull_data.py). Values as most recently reported in comparative 10-K / 10-Q filings.
A4: Income statement & cash flow | B4: FY2021 | C4: FY2022 | D4: FY2023 | E4: FY2024 | F4: FY2025 | G4: H1 2025 | H4: H1 2026
A5: Revenues | B5: 292111 | C5: 322467 | D5: 357776 | E5: 372809 | F5: 402067 | G5: 193503 | H5: 206522
A6: Operating income (GAAP) | B6: 13310 | C6: 7954 | D6: 13743 | E6: 8516 | F6: 4660 | G6: 5755 | H6: 9383
A7: Depreciation & amortization (cash flow statement) | B7: 4486 | C7: 4224 | D7: 4366 | E7: 4597 | F7: 4606 | G7: 2325 | H7: 2241
A8: Interest expense | B8: 2503 | C8: 2287 | D8: 2658 | E8: 2958 | F8: 3119 | G8: 1548 | H8: 1531 | J8: FY2021: InterestExpense tag; FY2022+: InterestExpenseNonoperating (identical in overlap years)
A9: Net income attributable to CVS Health | B9: 8001 | C9: 4311 | D9: 8344 | E9: 4614 | F9: 1768 | G9: 2800 | H9: 5922
A10: Net cash provided by operating activities | B10: 18265 | C10: 16177 | D10: 13426 | E10: 9107 | F10: 10639 | G10: 6453 | H10: 10594
A11: Capital expenditures (payments to acquire PP&E) | B11: 2520 | C11: 2727 | D11: 3031 | E11: 2781 | F11: 2832 | G11: 1350 | H11: 1540
A12: Dividends paid | B12: 2625 | C12: 2907 | D12: 3132 | E12: 3373 | F12: 3397 | G12: 1706 | H12: 1725
A13: Weighted avg diluted shares (millions) | B13: 1329 | C13: 1323 | D13: 1290 | E13: 1262 | F13: 1271 | G13: 1267 | H13: 1283
A15: Non-recurring adjustments added back to EBITDA | B15: FY2021 | C15: FY2022 | D15: FY2023 | E15: FY2024 | F15: FY2025 | I15: LTM (Jul-25–Jun-26)
A16: Goodwill impairment | B16: 431 | C16: 0 | D16: 0 | E16: 0 | F16: 5725 | I16: 5725
A17: Opioid litigation charges / accrual changes | B17: 0 | C17: 5803 | D17: 0 | E17: 100 | F17: 320 | I17: 320
A18: Legacy litigation charges | B18: 0 | C18: 0 | D18: 0 | E18: 0 | F18: 1220 | I18: 0
A19: Loss on assets held for sale | B19: 0 | C19: 2533 | D19: 349 | E19: 0 | F19: 0 | I19: 0
A20: Restructuring charges | B20: 0 | C20: 0 | D20: 507 | E20: 1179 | F20: 0 | I20: 0
A21: Total adjustments | B21: =SUM(B16:B20) | C21: =SUM(C16:C20) | D21: =SUM(D16:D20) | E21: =SUM(E16:E20) | F21: =SUM(F16:F20) | I21: =SUM(I16:I20)
A22: LTM add-backs are only the items recorded inside Jul 2025–Jun 2026 (Q3 2025 goodwill impairment and opioid accrual charge). The $1,220M legacy litigation charges were recorded in H1 2025 and sit outside the LTM window.
A24: Balance sheet (period-end) | B24: Dec 2021 | C24: Dec 2022 | D24: Dec 2023 | E24: Dec 2024 | F24: Dec 2025 | G24: Jun 2026
A25: Long-term debt, noncurrent | B25: 51971 | C25: 50476 | D25: 58638 | E25: 60527 | F25: 60502 | G25: 59452
A26: Current portion of long-term debt | B26: 4205 | C26: 1778 | D26: 2772 | E26: 3624 | F26: 4068 | G26: 1958
A27: Short-term borrowings (commercial paper) | B27: 0 | C27: 0 | D27: 200 | E27: 2119 | F27: 0 | G27: 0
A28: Total debt (carrying value) | B28: =SUM(B25:B27) | C28: =SUM(C25:C27) | D28: =SUM(D25:D27) | E28: =SUM(E25:E27) | F28: =SUM(F25:F27) | G28: =SUM(G25:G27)
A29: Cash and cash equivalents | B29: 9408 | C29: 12945 | D29: 8196 | E29: 8586 | F29: 8453 | G29: 11329
A30: Net debt | B30: =B28-B29 | C30: =C28-C29 | D30: =D28-D29 | E30: =E28-E29 | F30: =F28-F29 | G30: =G28-G29
A31: Operating lease liabilities, current | B31: 1646 | C31: 1678 | D31: 1741 | E31: 1751 | F31: 1737 | G31: 1914
A32: Operating lease liabilities, noncurrent | B32: 18177 | C32: 16800 | D32: 16034 | E32: 14899 | F32: 13643 | G32: 12982
A33: Finance lease liabilities, current | B33: 50 | C33: 59 | D33: 66 | E33: 65 | F33: 61 | G33: 61 | J33: Jun-2026 column carries Dec-2025 values: finance leases are not broken out in the Q2 2026 condensed balance sheet
A34: Finance lease liabilities, noncurrent | B34: 1250 | C34: 1406 | D34: 1325 | E34: 1295 | F34: 1265 | G34: 1265
A35: Total assets | B35: 232999 | C35: 228275 | D35: 249728 | E35: 253215 | F35: 253538 | G35: 253768
A36: Total shareholders' equity | B36: 75075 | C36: 71469 | D36: 76461 | E36: 75560 | F36: 75214 | G36: 79702
A37: Common shares outstanding (millions) | B37: 1322 | C37: 1300 | D37: 1288 | E37: 1260 | F37: 1271 | G37: 1278
A39: Debt maturity ladder — principal at Dec 31, 2025 (FY2025 10-K, borrowings note) | B39: Principal $M
A40: 2026 | B40: 4007
A41: 2027 | B41: 3379
A42: 2028 | B42: 5008
A43: 2029 | B43: 3758
A44: 2030 | B44: 4258
...

Sheet Ratios
A1: CVS Health — Ratio Analysis (all cells are live formulas from Inputs)
A2: LTM = twelve months ended Jun 30, 2026: FY2025 less H1 2025 plus H1 2026; balance-sheet items at Jun 30, 2026. $ millions unless noted.
B4: FY2021 | C4: FY2022 | D4: FY2023 | E4: FY2024 | F4: FY2025 | G4: LTM
A5: Revenues | B5: =Inputs!B5 | C5: =Inputs!C5 | D5: =Inputs!D5 | E5: =Inputs!E5 | F5: =Inputs!F5 | G5: =Inputs!F5-Inputs!G5+Inputs!H5
A6: Operating income (GAAP) | B6: =Inputs!B6 | C6: =Inputs!C6 | D6: =Inputs!D6 | E6: =Inputs!E6 | F6: =Inputs!F6 | G6: =Inputs!F6-Inputs!G6+Inputs!H6
A7: Plus: depreciation & amortization | B7: =Inputs!B7 | C7: =Inputs!C7 | D7: =Inputs!D7 | E7: =Inputs!E7 | F7: =Inputs!F7 | G7: =Inputs!F7-Inputs!G7+Inputs!H7
A8: Reported EBITDA | B8: =B6+B7 | C8: =C6+C7 | D8: =D6+D7 | E8: =E6+E7 | F8: =F6+F7 | G8: =G6+G7
A9: Plus: non-recurring adjustments (Inputs) | B9: =Inputs!B21 | C9: =Inputs!C21 | D9: =Inputs!D21 | E9: =Inputs!E21 | F9: =Inputs!F21 | G9: =Inputs!I21
A10: Adjusted EBITDA | B10: =B8+B9 | C10: =C8+C9 | D10: =D8+D9 | E10: =E8+E9 | F10: =F8+F9 | G10: =G8+G9
A11: Interest expense | B11: =Inputs!B8 | C11: =Inputs!C8 | D11: =Inputs!D8 | E11: =Inputs!E8 | F11: =Inputs!F8 | G11: =Inputs!F8-Inputs!G8+Inputs!H8
A12: Total debt | B12: =Inputs!B28 | C12: =Inputs!C28 | D12: =Inputs!D28 | E12: =Inputs!E28 | F12: =Inputs!F28 | G12: =Inputs!G28
A13: Cash and cash equivalents | B13: =Inputs!B29 | C13: =Inputs!C29 | D13: =Inputs!D29 | E13: =Inputs!E29 | F13: =Inputs!F29 | G13: =Inputs!G29
A14: Net debt | B14: =B12-B13 | C14: =C12-C13 | D14: =D12-D13 | E14: =E12-E13 | F14: =F12-F13 | G14: =G12-G13
A15: Gross leverage — Debt / Adjusted EBITDA | B15: =B12/B10 | C15: =C12/C10 | D15: =D12/D10 | E15: =E12/E10 | F15: =F12/F10 | G15: =G12/G10
A16: Gross leverage — Debt / Reported EBITDA | B16: =B12/B8 | C16: =C12/C8 | D16: =D12/D8 | E16: =E12/E8 | F16: =F12/F8 | G16: =G12/G8
A17: Net leverage — Net debt / Adjusted EBITDA | B17: =B14/B10 | C17: =C14/C10 | D17: =D14/D10 | E17: =E14/E10 | F17: =F14/F10 | G17: =G14/G10
A18: Interest coverage — Adjusted EBITDA / Interest | B18: =B10/B11 | C18: =C10/C11 | D18: =D10/D11 | E18: =E10/E11 | F18: =F10/F11 | G18: =G10/G11
A19: Interest coverage — Reported EBITDA / Interest | B19: =B8/B11 | C19: =C8/C11 | D19: =D8/D11 | E19: =E8/E11 | F19: =F8/F11 | G19: =G8/G11
A20: FFO (approx.) — net income + D&A + goodwill impairment | B20: =Inputs!B9+Inputs!B7+Inputs!B16 | C20: =Inputs!C9+Inputs!C7+Inputs!C16 | D20: =Inputs!D9+Inputs!D7+Inputs!D16 | E20: =Inputs!E9+Inputs!E7+Inputs!E16 | F20: =Inputs!F9+Inputs!F7+Inputs!F16 | G20: =Inputs!F9-Inputs!G9+Inputs!H9+Inputs!F7-Inputs!G7+Inputs!H7+Inputs!I16 | I20: Stated approximation: excludes deferred taxes, stock comp and other non-cash items
A21: FFO / Debt | B21: =B20/B12 | C21: =C20/C12 | D21: =D20/D12 | E21: =E20/E12 | F21: =F20/F12 | G21: =G20/G12
A22: FCF after dividends — OCF − capex − dividends paid | B22: =Inputs!B10-(Inputs!B11)-(Inputs!B12) | C22: =Inputs!C10-(Inputs!C11)-(Inputs!C12) | D22: =Inputs!D10-(Inputs!D11)-(Inputs!D12) | E22: =Inputs!E10-(Inputs!E11)-(Inputs!E12) | F22: =Inputs!F10-(Inputs!F11)-(Inputs!F12) | G22: =Inputs!F10-Inputs!G10+Inputs!H10-(Inputs!F11-Inputs!G11+Inputs!H11)-(Inputs!F12-Inputs!G12+Inputs!H12)
A23: FCF after dividends / Debt | B23: =B22/B12 | C23: =C22/C12 | D23: =D22/D12 | E23: =E22/E12 | F23: =F22/F12 | G23: =G22/G12
A24: Lease-adjusted debt — debt + operating + finance lease liabilities | B24: =B12+Inputs!B31+Inputs!B32+Inputs!B33+Inputs!B34 | C24: =C12+Inputs!C31+Inputs!C32+Inputs!C33+Inputs!C34 | D24: =D12+Inputs!D31+Inputs!D32+Inputs!D33+Inputs!D34 | E24: =E12+Inputs!E31+Inputs!E32+Inputs!E33+Inputs!E34 | F24: =F12+Inputs!F31+Inputs!F32+Inputs!F33+Inputs!F34 | G24: =G12+Inputs!G31+Inputs!G32+Inputs!G33+Inputs!G34
A25: Lease-adjusted leverage — Lease-adj. debt / Adjusted EBITDA | B25: =B24/B10 | C25: =C24/C10 | D25: =D24/D10 | E25: =E24/E10 | F25: =F24/F10 | G25: =G24/G10
A26: Adjusted EBITDA margin | B26: =B10/B5 | C26: =C10/C5 | D26: =D10/D5 | E26: =E10/E5 | F26: =F10/F5 | G26: =G10/G5
